<?xml version="1.0"?>
<robot name="simple_arm" xmlns:xacro="http://wiki.ros.org/xacro">
    <link name="base_link">
        <visual>
            <origin xyz="0 0 0.025" rpy="0 0 0"/>
            <geometry>
                <cylinder radius="0.1" length="0.05"/>
            </geometry>
            <material name="gray">
                <color rgba="1 0 0 1"/>
            </material>
        </visual>
        <collision>
            <origin xyz="0 0 0.025" rpy="0 0 0"/>
            <geometry>
                <cylinder radius="0.1" length="0.05"/>
            </geometry>
        </collision>
    </link>

    <joint name="joint1" type="fixed">
        <parent link="base_link"/>
        <child link="link_1"/>
        <origin xyz="0 0 0.05"/>
    </joint>

    <link name="link_1">
        <visual>
            <origin xyz="0 0 0.075" rpy="0 0 0"/>
            <geometry>
                <cylinder radius="0.07" length="0.15"/>
            </geometry>
            <material name="blue">
                <color rgba="0 0 1 1"/>
            </material>
        </visual>
        <collision>
            <origin xyz="0 0 0.075" rpy="0 0 0"/>
            <geometry>
                <cylinder radius="0.07" length="0.15"/>
            </geometry>
        </collision>
    </link>

    <joint name="joint2" type="revolute">
        <parent link="link_1"/>
        <child link="link_2"/>
        <origin xyz="0 0 0.15"/>
        <axis xyz="0 0 1"/>
        <limit effort="5" velocity="2.0" lower="-3.10" upper="3.10"/>
    </joint>

    <link name="link_2">
        <visual>
            <origin xyz="0 0 0.075" rpy="0 0 0"/>
            <geometry>
                <cylinder radius="0.07" length="0.15"/>
            </geometry>
            <material name="blue">
                <color rgba="0 0 1 1"/>
            </material>
        </visual>
        <collision>
            <origin xyz="0 0 0.075" rpy="0 0 0"/>
            <geometry>
                <cylinder radius="0.07" length="0.15"/>
            </geometry>
        </collision>
    </link>

    <joint name="joint3" type="revolute">
        <parent link="link_2"/>
        <child link="link_3"/>
        <origin xyz="0 0 0.15"/>
        <axis xyz="1 0 0"/>
        <limit effort="5" velocity="2.0" lower="-2.13" upper="2.13"/>
    </joint>

    <link name="link_3">
        <visual>
            <origin xyz="0 0 0.15" rpy="0 0 0"/>
            <geometry>
                <box size="0.12 0.12 0.3"/>
            </geometry>
            <material name="blue">
                <color rgba="0 1 1 1"/>
            </material>
        </visual>
        <collision>
            <origin xyz="0 0 0.15" rpy="0 0 0"/>
            <geometry>
                <box size="0.12 0.12 0.3"/>
            </geometry>
        </collision>
    </link>

    <joint name="joint4" type="revolute">
        <parent link="link_3"/>
        <child link="link_4"/>
        <origin xyz="0 0 0.3"/>
        <axis xyz="1 0 0"/>
        <limit effort="5" velocity="2.0" lower="-2.65" upper="2.65"/>
    </joint>

    <link name="link_4">
        <visual>
           <origin xyz="0 0 0.05" rpy="0 0 0"/>
            <geometry>
                <cylinder radius="0.05" length="0.1"/>
            </geometry>
            <material name="blue">
                <color rgba="0 1 0 1"/>
            </material>
        </visual>
        <collision>
             <origin xyz="0 0 0.05" rpy="0 0 0"/>
            <geometry>
                 <cylinder radius="0.05" length="0.1"/>
            </geometry>
        </collision>
    </link>

    <joint name="joint5" type="revolute">
        <parent link="link_4"/>
        <child link="link_5"/>
        <origin xyz="0 0 0.1"/>
        <axis xyz="0 0 1"/>
        <limit effort="5" velocity="2.0" lower="-3.10" upper="3.10"/>
    </joint>

    <link name="link_5">
        <visual>
           <origin xyz="0 0 0.05" rpy="0 0 0"/>
            <geometry>
                <cylinder radius="0.05" length="0.1"/>
            </geometry>
            <material name="blue">
                <color rgba="0 1 0 1"/>
            </material>
        </visual>
        <collision>
             <origin xyz="0 0 0.05" rpy="0 0 0"/>
            <geometry>
                <cylinder radius="0.05" length="0.1"/>
            </geometry>
        </collision>
    </link>

  <joint name="joint6" type="revolute">
        <parent link="link_5"/>
        <child link="link_6"/>
        <origin xyz="0 0 0.1"/>
        <axis xyz="1 0 0"/>
        <limit effort="5" velocity="2.0" lower="-2.65" upper="2.65"/>
    </joint>

    <link name="link_6">
        <visual>
            <origin xyz="0 0 0.04" rpy="0 0 0"/>
            <geometry>
                <box size="0.08 0.08 0.08"/>
            </geometry>
            <material name="blue">
                <color rgba="1 1 0 1"/>
            </material>
        </visual>
        <collision>
            <origin xyz="0 0 0.04" rpy="0 0 0"/>
            <geometry>
                <box size="0.08 0.08 0.08"/>
            </geometry>
        </collision>
    </link>

    <joint name="joint7" type="revolute">
        <parent link="link_6"/>
        <child link="link_7"/>
        <origin xyz="0 0 0.08"/>
        <axis xyz="0 0 1"/>
        <limit effort="5" velocity="2.0" lower="-3.10" upper="3.10"/>
    </joint>

    <link name="link_7">
        <visual>
           <origin xyz="0 0 0.035" rpy="0 0 0"/>
            <geometry>
                <cylinder radius="0.04" length="0.07"/>
            </geometry>
            <material name="blue">
                <color rgba="0 1 0 1"/>
            </material>
        </visual>
        <collision>
            <origin xyz="0 0 0.035" rpy="0 0 0"/>
            <geometry>
                <cylinder radius="0.04" length="0.07"/>
            </geometry>
        </collision>
    </link>


    <joint name="joint8" type="fixed">
        <parent link="link_7"/>
        <child link="link_8"/>
        <origin xyz="0 0 0.07"/>
    </joint>

    <link name="link_8">
        <visual>
            <origin xyz="0 0 0.02" rpy="0 0 0"/>
            <geometry>
                <box size="0.04 0.04 0.04"/>
            </geometry>
            <material name="blue">
                <color rgba="1 1 0 1"/>
            </material>
        </visual>
        <collision>
            <origin xyz="0 0 0.02" rpy="0 0 0"/>
            <geometry>
                <box size="0.04 0.04 0.04"/>
            </geometry>
        </collision>
    </link>

     <joint name="joint9" type="prismatic">
        <parent link="link_8"/>
        <child link="link_9"/>
        <origin xyz="0.035 0 0.04"/>
        <axis xyz="-1 0 0"/>
        <limit effort="5" velocity="2.0" lower="0" upper="0.025"/>
    </joint>

    <link name="link_9">
        <visual>
            <origin xyz="0 0 0.025" rpy="0 0 0"/>
            <geometry>
                <box size="0.005 0.05 0.05"/>
            </geometry>
            <material name="blue">
                <color rgba="1 1 0 1"/>
            </material>
        </visual>
        <collision>
            <origin xyz="0 0 0.025" rpy="0 0 0"/>
            <geometry>
                <box size="0.005 0.05 0.05"/>
            </geometry>
        </collision>
    </link>

     <joint name="joint10" type="prismatic">
        <parent link="link_8"/>
        <child link="link_10"/>
        <origin xyz="-0.035 0 0.04"/>
        <axis xyz="1 0 0"/>
        <limit effort="5" velocity="2.0" lower="0" upper="0.025"/>
    </joint>

    <link name="link_10">
        <visual>
            <origin xyz="0 0 0.025" rpy="0 0 0"/>
            <geometry>
                <box size="0.005 0.05 0.05"/>
            </geometry>
            <material name="blue">
                <color rgba="1 1 0 1"/>
            </material>
        </visual>
        <collision>
            <origin xyz="0 0 0.025" rpy="0 0 0"/>
            <geometry>
                <box size="0.005 0.05 0.05"/>
            </geometry>
        </collision>
    </link>
</robot>